[2025-09-18T08:07:49.527+0000] {local_task_job_runner.py:123} INFO - ::group::Pre task execution logs
[2025-09-18T08:07:49.550+0000] {taskinstance.py:2612} INFO - Dependencies all met for dep_context=non-requeueable deps ti=<TaskInstance: Dashboard_pipeline.dataingestion1 manual__2025-09-18T08:07:45.825217+00:00 [queued]>
[2025-09-18T08:07:49.560+0000] {taskinstance.py:2612} INFO - Dependencies all met for dep_context=requeueable deps ti=<TaskInstance: Dashboard_pipeline.dataingestion1 manual__2025-09-18T08:07:45.825217+00:00 [queued]>
[2025-09-18T08:07:49.560+0000] {taskinstance.py:2865} INFO - Starting attempt 1 of 2
[2025-09-18T08:07:49.580+0000] {taskinstance.py:2888} INFO - Executing <Task(BashOperator): dataingestion1> on 2025-09-18 08:07:45.825217+00:00
[2025-09-18T08:07:49.591+0000] {warnings.py:112} WARNING - /home/***/.local/lib/python3.12/site-packages/***/task/task_runner/standard_task_runner.py:70: DeprecationWarning: This process (pid=1438) is multi-threaded, use of fork() may lead to deadlocks in the child.
  pid = os.fork()

[2025-09-18T08:07:49.594+0000] {standard_task_runner.py:72} INFO - Started process 1440 to run task
[2025-09-18T08:07:49.594+0000] {standard_task_runner.py:104} INFO - Running: ['***', 'tasks', 'run', 'Dashboard_pipeline', 'dataingestion1', 'manual__2025-09-18T08:07:45.825217+00:00', '--job-id', '61', '--raw', '--subdir', 'DAGS_FOLDER/Dashboard-pipeline.py', '--cfg-path', '/tmp/tmpf4ljwsxj']
[2025-09-18T08:07:49.596+0000] {standard_task_runner.py:105} INFO - Job 61: Subtask dataingestion1
[2025-09-18T08:07:49.697+0000] {task_command.py:467} INFO - Running <TaskInstance: Dashboard_pipeline.dataingestion1 manual__2025-09-18T08:07:45.825217+00:00 [running]> on host 7f8c5cf1dc7b
[2025-09-18T08:07:49.866+0000] {taskinstance.py:3131} INFO - Exporting env vars: AIRFLOW_CTX_DAG_OWNER='***' AIRFLOW_CTX_DAG_ID='Dashboard_pipeline' AIRFLOW_CTX_TASK_ID='dataingestion1' AIRFLOW_CTX_EXECUTION_DATE='2025-09-18T08:07:45.825217+00:00' AIRFLOW_CTX_TRY_NUMBER='1' AIRFLOW_CTX_DAG_RUN_ID='manual__2025-09-18T08:07:45.825217+00:00'
[2025-09-18T08:07:49.870+0000] {logging_mixin.py:190} INFO - Task instance is in running state
[2025-09-18T08:07:49.872+0000] {logging_mixin.py:190} INFO -  Previous state of the Task instance: queued
[2025-09-18T08:07:49.873+0000] {logging_mixin.py:190} INFO - Current task name:dataingestion1 state:running start_date:2025-09-18 08:07:49.551449+00:00
[2025-09-18T08:07:49.874+0000] {logging_mixin.py:190} INFO - Dag name:Dashboard_pipeline and current dag run status:running
[2025-09-18T08:07:49.876+0000] {taskinstance.py:731} INFO - ::endgroup::
[2025-09-18T08:07:49.878+0000] {subprocess.py:63} INFO - Tmp dir root location: /tmp
[2025-09-18T08:07:49.881+0000] {subprocess.py:75} INFO - Running command: ['/usr/bin/bash', '-c', 'python D:/News-team-individual dashboards/Python-pipeline/dataingestion1.py']
[2025-09-18T08:07:49.913+0000] {subprocess.py:86} INFO - Output:
[2025-09-18T08:07:49.987+0000] {subprocess.py:93} INFO - python: can't open file '/tmp/***tmpb4xeyvbw/D:/News-team-individual': [Errno 2] No such file or directory
[2025-09-18T08:07:49.995+0000] {subprocess.py:97} INFO - Command exited with return code 2
[2025-09-18T08:07:50.030+0000] {taskinstance.py:3310} ERROR - Task failed with exception
Traceback (most recent call last):
  File "/home/airflow/.local/lib/python3.12/site-packages/airflow/models/taskinstance.py", line 767, in _execute_task
    result = _execute_callable(context=context, **execute_callable_kwargs)
             ^^^^^^^^^^^^^^^^^^^^^^^^^^^^^^^^^^^^^^^^^^^^^^^^^^^^^^^^^^^^^
  File "/home/airflow/.local/lib/python3.12/site-packages/airflow/models/taskinstance.py", line 733, in _execute_callable
    return ExecutionCallableRunner(
           ^^^^^^^^^^^^^^^^^^^^^^^^
  File "/home/airflow/.local/lib/python3.12/site-packages/airflow/utils/operator_helpers.py", line 252, in run
    return self.func(*args, **kwargs)
           ^^^^^^^^^^^^^^^^^^^^^^^^^^
  File "/home/airflow/.local/lib/python3.12/site-packages/airflow/models/baseoperator.py", line 406, in wrapper
    return func(self, *args, **kwargs)
           ^^^^^^^^^^^^^^^^^^^^^^^^^^^
  File "/home/airflow/.local/lib/python3.12/site-packages/airflow/operators/bash.py", line 249, in execute
    raise AirflowException(
airflow.exceptions.AirflowException: Bash command failed. The command returned a non-zero exit code 2.
[2025-09-18T08:07:50.049+0000] {logging_mixin.py:190} INFO - Task instance in failure state
[2025-09-18T08:07:50.049+0000] {logging_mixin.py:190} INFO - Task start:2025-09-18 08:07:49.551449+00:00 end:2025-09-18 08:07:50.048147+00:00 duration:0.496698
[2025-09-18T08:07:50.050+0000] {logging_mixin.py:190} INFO - Task:<Task(BashOperator): dataingestion1> dag:<DAG: Dashboard_pipeline> dagrun:<DagRun Dashboard_pipeline @ 2025-09-18 08:07:45.825217+00:00: manual__2025-09-18T08:07:45.825217+00:00, state:running, queued_at: 2025-09-18 08:07:45.969331+00:00. externally triggered: True>
[2025-09-18T08:07:50.051+0000] {logging_mixin.py:190} INFO - Failure caused by Bash command failed. The command returned a non-zero exit code 2.
[2025-09-18T08:07:50.051+0000] {taskinstance.py:1225} INFO - Marking task as UP_FOR_RETRY. dag_id=Dashboard_pipeline, task_id=dataingestion1, run_id=manual__2025-09-18T08:07:45.825217+00:00, execution_date=20250918T080745, start_date=20250918T080749, end_date=20250918T080750
[2025-09-18T08:07:50.077+0000] {taskinstance.py:340} INFO - ::group::Post task execution logs
[2025-09-18T08:07:50.078+0000] {standard_task_runner.py:124} ERROR - Failed to execute job 61 for task dataingestion1 (Bash command failed. The command returned a non-zero exit code 2.; 1440)
Traceback (most recent call last):
  File "/home/airflow/.local/lib/python3.12/site-packages/airflow/task/task_runner/standard_task_runner.py", line 117, in _start_by_fork
    ret = args.func(args, dag=self.dag)
          ^^^^^^^^^^^^^^^^^^^^^^^^^^^^^
  File "/home/airflow/.local/lib/python3.12/site-packages/airflow/cli/cli_config.py", line 49, in command
    return func(*args, **kwargs)
           ^^^^^^^^^^^^^^^^^^^^^
  File "/home/airflow/.local/lib/python3.12/site-packages/airflow/utils/cli.py", line 115, in wrapper
    return f(*args, **kwargs)
           ^^^^^^^^^^^^^^^^^^
  File "/home/airflow/.local/lib/python3.12/site-packages/airflow/cli/commands/task_command.py", line 483, in task_run
    task_return_code = _run_task_by_selected_method(args, _dag, ti)
                       ^^^^^^^^^^^^^^^^^^^^^^^^^^^^^^^^^^^^^^^^^^^^
  File "/home/airflow/.local/lib/python3.12/site-packages/airflow/cli/commands/task_command.py", line 256, in _run_task_by_selected_method
    return _run_raw_task(args, ti)
           ^^^^^^^^^^^^^^^^^^^^^^^
  File "/home/airflow/.local/lib/python3.12/site-packages/airflow/cli/commands/task_command.py", line 341, in _run_raw_task
    return ti._run_raw_task(
           ^^^^^^^^^^^^^^^^^
  File "/home/airflow/.local/lib/python3.12/site-packages/airflow/utils/session.py", line 97, in wrapper
    return func(*args, session=session, **kwargs)
           ^^^^^^^^^^^^^^^^^^^^^^^^^^^^^^^^^^^^^^
  File "/home/airflow/.local/lib/python3.12/site-packages/airflow/models/taskinstance.py", line 3004, in _run_raw_task
    return _run_raw_task(
           ^^^^^^^^^^^^^^
  File "/home/airflow/.local/lib/python3.12/site-packages/airflow/models/taskinstance.py", line 273, in _run_raw_task
    TaskInstance._execute_task_with_callbacks(
  File "/home/airflow/.local/lib/python3.12/site-packages/airflow/models/taskinstance.py", line 3158, in _execute_task_with_callbacks
    result = self._execute_task(context, task_orig)
             ^^^^^^^^^^^^^^^^^^^^^^^^^^^^^^^^^^^^^^
  File "/home/airflow/.local/lib/python3.12/site-packages/airflow/models/taskinstance.py", line 3182, in _execute_task
    return _execute_task(self, context, task_orig)
           ^^^^^^^^^^^^^^^^^^^^^^^^^^^^^^^^^^^^^^^
  File "/home/airflow/.local/lib/python3.12/site-packages/airflow/models/taskinstance.py", line 767, in _execute_task
    result = _execute_callable(context=context, **execute_callable_kwargs)
             ^^^^^^^^^^^^^^^^^^^^^^^^^^^^^^^^^^^^^^^^^^^^^^^^^^^^^^^^^^^^^
  File "/home/airflow/.local/lib/python3.12/site-packages/airflow/models/taskinstance.py", line 733, in _execute_callable
    return ExecutionCallableRunner(
           ^^^^^^^^^^^^^^^^^^^^^^^^
  File "/home/airflow/.local/lib/python3.12/site-packages/airflow/utils/operator_helpers.py", line 252, in run
    return self.func(*args, **kwargs)
           ^^^^^^^^^^^^^^^^^^^^^^^^^^
  File "/home/airflow/.local/lib/python3.12/site-packages/airflow/models/baseoperator.py", line 406, in wrapper
    return func(self, *args, **kwargs)
           ^^^^^^^^^^^^^^^^^^^^^^^^^^^
  File "/home/airflow/.local/lib/python3.12/site-packages/airflow/operators/bash.py", line 249, in execute
    raise AirflowException(
airflow.exceptions.AirflowException: Bash command failed. The command returned a non-zero exit code 2.
[2025-09-18T08:07:50.137+0000] {local_task_job_runner.py:266} INFO - Task exited with return code 1
[2025-09-18T08:07:50.179+0000] {taskinstance.py:3900} INFO - 0 downstream tasks scheduled from follow-on schedule check
[2025-09-18T08:07:50.184+0000] {local_task_job_runner.py:245} INFO - ::endgroup::
