[2025-09-18T09:17:48.887+0000] {local_task_job_runner.py:123} INFO - ::group::Pre task execution logs
[2025-09-18T09:17:48.906+0000] {taskinstance.py:2612} INFO - Dependencies all met for dep_context=non-requeueable deps ti=<TaskInstance: Dashboard_pipeline.dataingestion1 manual__2025-09-18T09:12:43.526712+00:00 [queued]>
[2025-09-18T09:17:48.914+0000] {taskinstance.py:2612} INFO - Dependencies all met for dep_context=requeueable deps ti=<TaskInstance: Dashboard_pipeline.dataingestion1 manual__2025-09-18T09:12:43.526712+00:00 [queued]>
[2025-09-18T09:17:48.915+0000] {taskinstance.py:2865} INFO - Starting attempt 2 of 2
[2025-09-18T09:17:48.931+0000] {taskinstance.py:2888} INFO - Executing <Task(BashOperator): dataingestion1> on 2025-09-18 09:12:43.526712+00:00
[2025-09-18T09:17:48.939+0000] {warnings.py:112} WARNING - /home/***/.local/lib/python3.12/site-packages/***/task/task_runner/standard_task_runner.py:70: DeprecationWarning: This process (pid=2329) is multi-threaded, use of fork() may lead to deadlocks in the child.
  pid = os.fork()

[2025-09-18T09:17:48.942+0000] {standard_task_runner.py:72} INFO - Started process 2331 to run task
[2025-09-18T09:17:48.942+0000] {standard_task_runner.py:104} INFO - Running: ['***', 'tasks', 'run', 'Dashboard_pipeline', 'dataingestion1', 'manual__2025-09-18T09:12:43.526712+00:00', '--job-id', '64', '--raw', '--subdir', 'DAGS_FOLDER/Dashboard-pipeline.py', '--cfg-path', '/tmp/tmpo9smcfvw']
[2025-09-18T09:17:48.944+0000] {standard_task_runner.py:105} INFO - Job 64: Subtask dataingestion1
[2025-09-18T09:17:49.026+0000] {task_command.py:467} INFO - Running <TaskInstance: Dashboard_pipeline.dataingestion1 manual__2025-09-18T09:12:43.526712+00:00 [running]> on host 7f8c5cf1dc7b
[2025-09-18T09:17:49.115+0000] {taskinstance.py:3131} INFO - Exporting env vars: AIRFLOW_CTX_DAG_OWNER='***' AIRFLOW_CTX_DAG_ID='Dashboard_pipeline' AIRFLOW_CTX_TASK_ID='dataingestion1' AIRFLOW_CTX_EXECUTION_DATE='2025-09-18T09:12:43.526712+00:00' AIRFLOW_CTX_TRY_NUMBER='2' AIRFLOW_CTX_DAG_RUN_ID='manual__2025-09-18T09:12:43.526712+00:00'
[2025-09-18T09:17:49.116+0000] {logging_mixin.py:190} INFO - Task instance is in running state
[2025-09-18T09:17:49.117+0000] {logging_mixin.py:190} INFO -  Previous state of the Task instance: queued
[2025-09-18T09:17:49.118+0000] {logging_mixin.py:190} INFO - Current task name:dataingestion1 state:running start_date:2025-09-18 09:17:48.907028+00:00
[2025-09-18T09:17:49.118+0000] {logging_mixin.py:190} INFO - Dag name:Dashboard_pipeline and current dag run status:running
[2025-09-18T09:17:49.119+0000] {taskinstance.py:731} INFO - ::endgroup::
[2025-09-18T09:17:49.120+0000] {subprocess.py:63} INFO - Tmp dir root location: /tmp
[2025-09-18T09:17:49.122+0000] {subprocess.py:75} INFO - Running command: ['/usr/bin/bash', '-c', 'python D:/News-team-individual dashboards/Python-pipeline/dataingestion1.py']
[2025-09-18T09:17:49.137+0000] {subprocess.py:86} INFO - Output:
[2025-09-18T09:17:49.172+0000] {subprocess.py:93} INFO - python: can't open file '/tmp/***tmph7q__6i4/D:/News-team-individual': [Errno 2] No such file or directory
[2025-09-18T09:17:49.175+0000] {subprocess.py:97} INFO - Command exited with return code 2
[2025-09-18T09:17:49.191+0000] {taskinstance.py:3310} ERROR - Task failed with exception
Traceback (most recent call last):
  File "/home/airflow/.local/lib/python3.12/site-packages/airflow/models/taskinstance.py", line 767, in _execute_task
    result = _execute_callable(context=context, **execute_callable_kwargs)
             ^^^^^^^^^^^^^^^^^^^^^^^^^^^^^^^^^^^^^^^^^^^^^^^^^^^^^^^^^^^^^
  File "/home/airflow/.local/lib/python3.12/site-packages/airflow/models/taskinstance.py", line 733, in _execute_callable
    return ExecutionCallableRunner(
           ^^^^^^^^^^^^^^^^^^^^^^^^
  File "/home/airflow/.local/lib/python3.12/site-packages/airflow/utils/operator_helpers.py", line 252, in run
    return self.func(*args, **kwargs)
           ^^^^^^^^^^^^^^^^^^^^^^^^^^
  File "/home/airflow/.local/lib/python3.12/site-packages/airflow/models/baseoperator.py", line 406, in wrapper
    return func(self, *args, **kwargs)
           ^^^^^^^^^^^^^^^^^^^^^^^^^^^
  File "/home/airflow/.local/lib/python3.12/site-packages/airflow/operators/bash.py", line 249, in execute
    raise AirflowException(
airflow.exceptions.AirflowException: Bash command failed. The command returned a non-zero exit code 2.
[2025-09-18T09:17:49.196+0000] {logging_mixin.py:190} INFO - Task instance in failure state
[2025-09-18T09:17:49.197+0000] {logging_mixin.py:190} INFO - Task start:2025-09-18 09:17:48.907028+00:00 end:2025-09-18 09:17:49.195743+00:00 duration:0.288715
[2025-09-18T09:17:49.198+0000] {logging_mixin.py:190} INFO - Task:<Task(BashOperator): dataingestion1> dag:<DAG: Dashboard_pipeline> dagrun:<DagRun Dashboard_pipeline @ 2025-09-18 09:12:43.526712+00:00: manual__2025-09-18T09:12:43.526712+00:00, state:running, queued_at: 2025-09-18 09:12:43.566953+00:00. externally triggered: True>
[2025-09-18T09:17:49.199+0000] {logging_mixin.py:190} INFO - Failure caused by Bash command failed. The command returned a non-zero exit code 2.
[2025-09-18T09:17:49.199+0000] {taskinstance.py:1225} INFO - Marking task as FAILED. dag_id=Dashboard_pipeline, task_id=dataingestion1, run_id=manual__2025-09-18T09:12:43.526712+00:00, execution_date=20250918T091243, start_date=20250918T091748, end_date=20250918T091749
[2025-09-18T09:17:49.215+0000] {taskinstance.py:340} INFO - ::group::Post task execution logs
[2025-09-18T09:17:49.216+0000] {standard_task_runner.py:124} ERROR - Failed to execute job 64 for task dataingestion1 (Bash command failed. The command returned a non-zero exit code 2.; 2331)
Traceback (most recent call last):
  File "/home/airflow/.local/lib/python3.12/site-packages/airflow/task/task_runner/standard_task_runner.py", line 117, in _start_by_fork
    ret = args.func(args, dag=self.dag)
          ^^^^^^^^^^^^^^^^^^^^^^^^^^^^^
  File "/home/airflow/.local/lib/python3.12/site-packages/airflow/cli/cli_config.py", line 49, in command
    return func(*args, **kwargs)
           ^^^^^^^^^^^^^^^^^^^^^
  File "/home/airflow/.local/lib/python3.12/site-packages/airflow/utils/cli.py", line 115, in wrapper
    return f(*args, **kwargs)
           ^^^^^^^^^^^^^^^^^^
  File "/home/airflow/.local/lib/python3.12/site-packages/airflow/cli/commands/task_command.py", line 483, in task_run
    task_return_code = _run_task_by_selected_method(args, _dag, ti)
                       ^^^^^^^^^^^^^^^^^^^^^^^^^^^^^^^^^^^^^^^^^^^^
  File "/home/airflow/.local/lib/python3.12/site-packages/airflow/cli/commands/task_command.py", line 256, in _run_task_by_selected_method
    return _run_raw_task(args, ti)
           ^^^^^^^^^^^^^^^^^^^^^^^
  File "/home/airflow/.local/lib/python3.12/site-packages/airflow/cli/commands/task_command.py", line 341, in _run_raw_task
    return ti._run_raw_task(
           ^^^^^^^^^^^^^^^^^
  File "/home/airflow/.local/lib/python3.12/site-packages/airflow/utils/session.py", line 97, in wrapper
    return func(*args, session=session, **kwargs)
           ^^^^^^^^^^^^^^^^^^^^^^^^^^^^^^^^^^^^^^
  File "/home/airflow/.local/lib/python3.12/site-packages/airflow/models/taskinstance.py", line 3004, in _run_raw_task
    return _run_raw_task(
           ^^^^^^^^^^^^^^
  File "/home/airflow/.local/lib/python3.12/site-packages/airflow/models/taskinstance.py", line 273, in _run_raw_task
    TaskInstance._execute_task_with_callbacks(
  File "/home/airflow/.local/lib/python3.12/site-packages/airflow/models/taskinstance.py", line 3158, in _execute_task_with_callbacks
    result = self._execute_task(context, task_orig)
             ^^^^^^^^^^^^^^^^^^^^^^^^^^^^^^^^^^^^^^
  File "/home/airflow/.local/lib/python3.12/site-packages/airflow/models/taskinstance.py", line 3182, in _execute_task
    return _execute_task(self, context, task_orig)
           ^^^^^^^^^^^^^^^^^^^^^^^^^^^^^^^^^^^^^^^
  File "/home/airflow/.local/lib/python3.12/site-packages/airflow/models/taskinstance.py", line 767, in _execute_task
    result = _execute_callable(context=context, **execute_callable_kwargs)
             ^^^^^^^^^^^^^^^^^^^^^^^^^^^^^^^^^^^^^^^^^^^^^^^^^^^^^^^^^^^^^
  File "/home/airflow/.local/lib/python3.12/site-packages/airflow/models/taskinstance.py", line 733, in _execute_callable
    return ExecutionCallableRunner(
           ^^^^^^^^^^^^^^^^^^^^^^^^
  File "/home/airflow/.local/lib/python3.12/site-packages/airflow/utils/operator_helpers.py", line 252, in run
    return self.func(*args, **kwargs)
           ^^^^^^^^^^^^^^^^^^^^^^^^^^
  File "/home/airflow/.local/lib/python3.12/site-packages/airflow/models/baseoperator.py", line 406, in wrapper
    return func(self, *args, **kwargs)
           ^^^^^^^^^^^^^^^^^^^^^^^^^^^
  File "/home/airflow/.local/lib/python3.12/site-packages/airflow/operators/bash.py", line 249, in execute
    raise AirflowException(
airflow.exceptions.AirflowException: Bash command failed. The command returned a non-zero exit code 2.
[2025-09-18T09:17:49.239+0000] {local_task_job_runner.py:266} INFO - Task exited with return code 1
[2025-09-18T09:17:49.270+0000] {taskinstance.py:3900} INFO - 0 downstream tasks scheduled from follow-on schedule check
[2025-09-18T09:17:49.279+0000] {local_task_job_runner.py:245} INFO - ::endgroup::
